[2023-06-14T20:53:33.481+0000] {taskinstance.py:1103} INFO - Dependencies all met for dep_context=non-requeueable deps ti=<TaskInstance: get_university_api_send_psql.send_to_postgresql manual__2023-06-14T20:53:08.599882+00:00 [queued]>
[2023-06-14T20:53:33.499+0000] {taskinstance.py:1103} INFO - Dependencies all met for dep_context=requeueable deps ti=<TaskInstance: get_university_api_send_psql.send_to_postgresql manual__2023-06-14T20:53:08.599882+00:00 [queued]>
[2023-06-14T20:53:33.501+0000] {taskinstance.py:1308} INFO - Starting attempt 1 of 1
[2023-06-14T20:53:33.529+0000] {taskinstance.py:1327} INFO - Executing <Task(PythonOperator): send_to_postgresql> on 2023-06-14 20:53:08.599882+00:00
[2023-06-14T20:53:33.545+0000] {standard_task_runner.py:57} INFO - Started process 10440 to run task
[2023-06-14T20:53:33.561+0000] {standard_task_runner.py:84} INFO - Running: ['***', 'tasks', 'run', 'get_university_api_send_psql', 'send_to_postgresql', 'manual__2023-06-14T20:53:08.599882+00:00', '--job-id', '1723', '--raw', '--subdir', 'DAGS_FOLDER/data-university-from-api-dag/data_university_from_api_dag.py', '--cfg-path', '/tmp/tmp2ban7nlw']
[2023-06-14T20:53:33.566+0000] {standard_task_runner.py:85} INFO - Job 1723: Subtask send_to_postgresql
[2023-06-14T20:53:33.662+0000] {task_command.py:410} INFO - Running <TaskInstance: get_university_api_send_psql.send_to_postgresql manual__2023-06-14T20:53:08.599882+00:00 [running]> on host cd01a659cc96
[2023-06-14T20:53:33.799+0000] {taskinstance.py:1547} INFO - Exporting env vars: AIRFLOW_CTX_DAG_OWNER='***' AIRFLOW_CTX_DAG_ID='get_university_api_send_psql' AIRFLOW_CTX_TASK_ID='send_to_postgresql' AIRFLOW_CTX_EXECUTION_DATE='2023-06-14T20:53:08.599882+00:00' AIRFLOW_CTX_TRY_NUMBER='1' AIRFLOW_CTX_DAG_RUN_ID='manual__2023-06-14T20:53:08.599882+00:00'
[2023-06-14T20:53:34.298+0000] {taskinstance.py:1824} ERROR - Task failed with exception
Traceback (most recent call last):
  File "/home/airflow/.local/lib/python3.7/site-packages/airflow/operators/python.py", line 181, in execute
    return_value = self.execute_callable()
  File "/home/airflow/.local/lib/python3.7/site-packages/airflow/operators/python.py", line 198, in execute_callable
    return self.python_callable(*self.op_args, **self.op_kwargs)
  File "/opt/airflow/dags/data-university-from-api-dag/data_university_from_api_dag.py", line 144, in _send_to_postgresql
    for my_country, my_alpha_two_code, my_name, my_state_province, my_domains, my_web_pages in zip(country, alpha_two_code,name,state_province,domains,web_pages):
TypeError: zip argument #1 must support iteration
[2023-06-14T20:53:34.323+0000] {taskinstance.py:1350} INFO - Marking task as FAILED. dag_id=get_university_api_send_psql, task_id=send_to_postgresql, execution_date=20230614T205308, start_date=20230614T205333, end_date=20230614T205334
[2023-06-14T20:53:34.344+0000] {standard_task_runner.py:109} ERROR - Failed to execute job 1723 for task send_to_postgresql (zip argument #1 must support iteration; 10440)
[2023-06-14T20:53:34.375+0000] {local_task_job_runner.py:225} INFO - Task exited with return code 1
[2023-06-14T20:53:34.506+0000] {taskinstance.py:2651} INFO - 0 downstream tasks scheduled from follow-on schedule check
