[2023-06-14T19:10:19.809+0000] {taskinstance.py:1103} INFO - Dependencies all met for dep_context=non-requeueable deps ti=<TaskInstance: get_university_api_send_psql.fetch_and_save manual__2023-06-14T19:10:16.245632+00:00 [queued]>
[2023-06-14T19:10:19.833+0000] {taskinstance.py:1103} INFO - Dependencies all met for dep_context=requeueable deps ti=<TaskInstance: get_university_api_send_psql.fetch_and_save manual__2023-06-14T19:10:16.245632+00:00 [queued]>
[2023-06-14T19:10:19.834+0000] {taskinstance.py:1308} INFO - Starting attempt 1 of 1
[2023-06-14T19:10:19.874+0000] {taskinstance.py:1327} INFO - Executing <Task(PythonOperator): fetch_and_save> on 2023-06-14 19:10:16.245632+00:00
[2023-06-14T19:10:19.886+0000] {standard_task_runner.py:57} INFO - Started process 8538 to run task
[2023-06-14T19:10:19.895+0000] {standard_task_runner.py:84} INFO - Running: ['***', 'tasks', 'run', 'get_university_api_send_psql', 'fetch_and_save', 'manual__2023-06-14T19:10:16.245632+00:00', '--job-id', '1546', '--raw', '--subdir', 'DAGS_FOLDER/data-university-from-api-dag/data_university_from_api_dag.py', '--cfg-path', '/tmp/tmpywlds_of']
[2023-06-14T19:10:19.899+0000] {standard_task_runner.py:85} INFO - Job 1546: Subtask fetch_and_save
[2023-06-14T19:10:20.068+0000] {task_command.py:410} INFO - Running <TaskInstance: get_university_api_send_psql.fetch_and_save manual__2023-06-14T19:10:16.245632+00:00 [running]> on host cd01a659cc96
[2023-06-14T19:10:20.240+0000] {taskinstance.py:1547} INFO - Exporting env vars: AIRFLOW_CTX_DAG_OWNER='***' AIRFLOW_CTX_DAG_ID='get_university_api_send_psql' AIRFLOW_CTX_TASK_ID='fetch_and_save' AIRFLOW_CTX_EXECUTION_DATE='2023-06-14T19:10:16.245632+00:00' AIRFLOW_CTX_TRY_NUMBER='1' AIRFLOW_CTX_DAG_RUN_ID='manual__2023-06-14T19:10:16.245632+00:00'
[2023-06-14T19:10:46.009+0000] {taskinstance.py:1824} ERROR - Task failed with exception
Traceback (most recent call last):
  File "/home/airflow/.local/lib/python3.7/site-packages/airflow/operators/python.py", line 181, in execute
    return_value = self.execute_callable()
  File "/home/airflow/.local/lib/python3.7/site-packages/airflow/operators/python.py", line 198, in execute_callable
    return self.python_callable(*self.op_args, **self.op_kwargs)
  File "/opt/airflow/dags/data-university-from-api-dag/data_university_from_api_dag.py", line 48, in _fetch_and_save
    writer.writerow(data)
  File "/usr/local/lib/python3.7/csv.py", line 155, in writerow
    return self.writer.writerow(self._dict_to_list(rowdict))
  File "/usr/local/lib/python3.7/csv.py", line 148, in _dict_to_list
    wrong_fields = rowdict.keys() - self.fieldnames
AttributeError: 'list' object has no attribute 'keys'
[2023-06-14T19:10:46.097+0000] {taskinstance.py:1350} INFO - Marking task as FAILED. dag_id=get_university_api_send_psql, task_id=fetch_and_save, execution_date=20230614T191016, start_date=20230614T191019, end_date=20230614T191046
[2023-06-14T19:10:46.191+0000] {standard_task_runner.py:109} ERROR - Failed to execute job 1546 for task fetch_and_save ('list' object has no attribute 'keys'; 8538)
[2023-06-14T19:10:46.228+0000] {local_task_job_runner.py:225} INFO - Task exited with return code 1
[2023-06-14T19:10:46.304+0000] {taskinstance.py:2651} INFO - 0 downstream tasks scheduled from follow-on schedule check
