[2024-02-06T13:45:41.950+0000] {taskinstance.py:1103} INFO - Dependencies all met for dep_context=non-requeueable deps ti=<TaskInstance: get_energy_data_send_psql.fetch_and_save manual__2024-02-06T13:45:25.568034+00:00 [queued]>
[2024-02-06T13:45:41.971+0000] {taskinstance.py:1103} INFO - Dependencies all met for dep_context=requeueable deps ti=<TaskInstance: get_energy_data_send_psql.fetch_and_save manual__2024-02-06T13:45:25.568034+00:00 [queued]>
[2024-02-06T13:45:41.973+0000] {taskinstance.py:1308} INFO - Starting attempt 1 of 1
[2024-02-06T13:45:42.008+0000] {taskinstance.py:1327} INFO - Executing <Task(PythonOperator): fetch_and_save> on 2024-02-06 13:45:25.568034+00:00
[2024-02-06T13:45:42.031+0000] {standard_task_runner.py:57} INFO - Started process 609 to run task
[2024-02-06T13:45:42.142+0000] {standard_task_runner.py:84} INFO - Running: ['***', 'tasks', 'run', 'get_energy_data_send_psql', 'fetch_and_save', 'manual__2024-02-06T13:45:25.568034+00:00', '--job-id', '16', '--raw', '--subdir', 'DAGS_FOLDER/energy-prod-cons-dag/data_energy_dag.py', '--cfg-path', '/tmp/tmp4d4mm898']
[2024-02-06T13:45:42.151+0000] {standard_task_runner.py:85} INFO - Job 16: Subtask fetch_and_save
[2024-02-06T13:45:42.319+0000] {task_command.py:410} INFO - Running <TaskInstance: get_energy_data_send_psql.fetch_and_save manual__2024-02-06T13:45:25.568034+00:00 [running]> on host 952b3f8a1a94
[2024-02-06T13:45:42.479+0000] {taskinstance.py:1547} INFO - Exporting env vars: AIRFLOW_CTX_DAG_OWNER='***' AIRFLOW_CTX_DAG_ID='get_energy_data_send_psql' AIRFLOW_CTX_TASK_ID='fetch_and_save' AIRFLOW_CTX_EXECUTION_DATE='2024-02-06T13:45:25.568034+00:00' AIRFLOW_CTX_TRY_NUMBER='1' AIRFLOW_CTX_DAG_RUN_ID='manual__2024-02-06T13:45:25.568034+00:00'
[2024-02-06T13:45:42.508+0000] {taskinstance.py:1824} ERROR - Task failed with exception
Traceback (most recent call last):
  File "/home/airflow/.local/lib/python3.7/site-packages/airflow/operators/python.py", line 181, in execute
    return_value = self.execute_callable()
  File "/home/airflow/.local/lib/python3.7/site-packages/airflow/operators/python.py", line 198, in execute_callable
    return self.python_callable(*self.op_args, **self.op_kwargs)
  File "/opt/airflow/dags/energy-prod-cons-dag/data_energy_dag.py", line 37, in _fetch_and_save
    aws_secret_access_key=configurations["aws_secret_access_key"]
  File "/home/airflow/.local/lib/python3.7/site-packages/boto3/__init__.py", line 92, in client
    return _get_default_session().client(*args, **kwargs)
TypeError: client() got an unexpected keyword argument 'bucket_name'
[2024-02-06T13:45:42.535+0000] {taskinstance.py:1350} INFO - Marking task as FAILED. dag_id=get_energy_data_send_psql, task_id=fetch_and_save, execution_date=20240206T134525, start_date=20240206T134541, end_date=20240206T134542
[2024-02-06T13:45:42.575+0000] {standard_task_runner.py:109} ERROR - Failed to execute job 16 for task fetch_and_save (client() got an unexpected keyword argument 'bucket_name'; 609)
[2024-02-06T13:45:42.618+0000] {local_task_job_runner.py:225} INFO - Task exited with return code 1
[2024-02-06T13:45:42.667+0000] {taskinstance.py:2651} INFO - 0 downstream tasks scheduled from follow-on schedule check
