[2023-06-14T13:13:06.932+0000] {taskinstance.py:1103} INFO - Dependencies all met for dep_context=non-requeueable deps ti=<TaskInstance: get_psql_send_s3.send_csv_s3 manual__2023-06-14T13:12:59.594998+00:00 [queued]>
[2023-06-14T13:13:06.987+0000] {taskinstance.py:1103} INFO - Dependencies all met for dep_context=requeueable deps ti=<TaskInstance: get_psql_send_s3.send_csv_s3 manual__2023-06-14T13:12:59.594998+00:00 [queued]>
[2023-06-14T13:13:06.989+0000] {taskinstance.py:1308} INFO - Starting attempt 1 of 1
[2023-06-14T13:13:07.015+0000] {taskinstance.py:1327} INFO - Executing <Task(PythonOperator): send_csv_s3> on 2023-06-14 13:12:59.594998+00:00
[2023-06-14T13:13:07.029+0000] {standard_task_runner.py:57} INFO - Started process 2531 to run task
[2023-06-14T13:13:07.043+0000] {standard_task_runner.py:84} INFO - Running: ['***', 'tasks', 'run', 'get_psql_send_s3', 'send_csv_s3', 'manual__2023-06-14T13:12:59.594998+00:00', '--job-id', '1508', '--raw', '--subdir', 'DAGS_FOLDER/end_to_end_pipeline_***.py', '--cfg-path', '/tmp/tmp2wqzpusp']
[2023-06-14T13:13:07.048+0000] {standard_task_runner.py:85} INFO - Job 1508: Subtask send_csv_s3
[2023-06-14T13:13:07.138+0000] {task_command.py:410} INFO - Running <TaskInstance: get_psql_send_s3.send_csv_s3 manual__2023-06-14T13:12:59.594998+00:00 [running]> on host cd01a659cc96
[2023-06-14T13:13:07.278+0000] {taskinstance.py:1547} INFO - Exporting env vars: AIRFLOW_CTX_DAG_OWNER='***' AIRFLOW_CTX_DAG_ID='get_psql_send_s3' AIRFLOW_CTX_TASK_ID='send_csv_s3' AIRFLOW_CTX_EXECUTION_DATE='2023-06-14T13:12:59.594998+00:00' AIRFLOW_CTX_TRY_NUMBER='1' AIRFLOW_CTX_DAG_RUN_ID='manual__2023-06-14T13:12:59.594998+00:00'
[2023-06-14T13:13:07.283+0000] {taskinstance.py:1824} ERROR - Task failed with exception
Traceback (most recent call last):
  File "/home/airflow/.local/lib/python3.7/site-packages/airflow/operators/python.py", line 181, in execute
    return_value = self.execute_callable()
  File "/home/airflow/.local/lib/python3.7/site-packages/airflow/operators/python.py", line 198, in execute_callable
    return self.python_callable(*self.op_args, **self.op_kwargs)
  File "/opt/airflow/dags/end_to_end_pipeline_airflow.py", line 96, in _send_csv_s3
    with open(CUR_DIR + "/configurations.json","r") as output:
FileNotFoundError: [Errno 2] No such file or directory: '/opt/airflow/dags/configurations.json'
[2023-06-14T13:13:07.299+0000] {taskinstance.py:1350} INFO - Marking task as FAILED. dag_id=get_psql_send_s3, task_id=send_csv_s3, execution_date=20230614T131259, start_date=20230614T131306, end_date=20230614T131307
[2023-06-14T13:13:07.323+0000] {standard_task_runner.py:109} ERROR - Failed to execute job 1508 for task send_csv_s3 ([Errno 2] No such file or directory: '/opt/airflow/dags/configurations.json'; 2531)
[2023-06-14T13:13:07.373+0000] {local_task_job_runner.py:225} INFO - Task exited with return code 1
[2023-06-14T13:13:07.410+0000] {taskinstance.py:2651} INFO - 0 downstream tasks scheduled from follow-on schedule check
