[2024-02-06T18:29:50.225+0000] {taskinstance.py:1103} INFO - Dependencies all met for dep_context=non-requeueable deps ti=<TaskInstance: get_energy_data_send_psql.fetch_and_save manual__2024-02-06T18:29:46.742259+00:00 [queued]>
[2024-02-06T18:29:50.245+0000] {taskinstance.py:1103} INFO - Dependencies all met for dep_context=requeueable deps ti=<TaskInstance: get_energy_data_send_psql.fetch_and_save manual__2024-02-06T18:29:46.742259+00:00 [queued]>
[2024-02-06T18:29:50.249+0000] {taskinstance.py:1308} INFO - Starting attempt 1 of 1
[2024-02-06T18:29:50.275+0000] {taskinstance.py:1327} INFO - Executing <Task(PythonOperator): fetch_and_save> on 2024-02-06 18:29:46.742259+00:00
[2024-02-06T18:29:50.288+0000] {standard_task_runner.py:57} INFO - Started process 5210 to run task
[2024-02-06T18:29:50.297+0000] {standard_task_runner.py:84} INFO - Running: ['***', 'tasks', 'run', 'get_energy_data_send_psql', 'fetch_and_save', 'manual__2024-02-06T18:29:46.742259+00:00', '--job-id', '112', '--raw', '--subdir', 'DAGS_FOLDER/energy-prod-cons-dag/data_energy_dag.py', '--cfg-path', '/tmp/tmp40b6ylg_']
[2024-02-06T18:29:50.303+0000] {standard_task_runner.py:85} INFO - Job 112: Subtask fetch_and_save
[2024-02-06T18:29:50.384+0000] {task_command.py:410} INFO - Running <TaskInstance: get_energy_data_send_psql.fetch_and_save manual__2024-02-06T18:29:46.742259+00:00 [running]> on host 952b3f8a1a94
[2024-02-06T18:29:50.544+0000] {taskinstance.py:1547} INFO - Exporting env vars: AIRFLOW_CTX_DAG_OWNER='***' AIRFLOW_CTX_DAG_ID='get_energy_data_send_psql' AIRFLOW_CTX_TASK_ID='fetch_and_save' AIRFLOW_CTX_EXECUTION_DATE='2024-02-06T18:29:46.742259+00:00' AIRFLOW_CTX_TRY_NUMBER='1' AIRFLOW_CTX_DAG_RUN_ID='manual__2024-02-06T18:29:46.742259+00:00'
[2024-02-06T18:29:53.124+0000] {warnings.py:110} WARNING - /home/***/.local/lib/python3.7/site-packages/***/operators/python.py:198: FutureWarning: The error_bad_lines argument has been deprecated and will be removed in a future version.


  return self.python_callable(*self.op_args, **self.op_kwargs)

[2024-02-06T18:29:55.871+0000] {logging_mixin.py:149} INFO - ******* STARTING columns ******  : Index(['operateur', 'annee', 'filiere', 'code_categorie_consommation',
       'libelle_categorie_consommation', 'code_grand_secteur',
       'libelle_grand_secteur', 'code_naf', 'libelle_secteur_naf2', 'conso',
       'pdl', 'indqual', 'nombre_mailles_secretisees', 'code_region',
       'libelle_region'],
      dtype='object')
[2024-02-06T18:29:55.875+0000] {logging_mixin.py:149} INFO - Strip leading and trailing whitespaces from column names
[2024-02-06T18:29:55.880+0000] {taskinstance.py:1824} ERROR - Task failed with exception
Traceback (most recent call last):
  File "/home/airflow/.local/lib/python3.7/site-packages/airflow/operators/python.py", line 181, in execute
    return_value = self.execute_callable()
  File "/home/airflow/.local/lib/python3.7/site-packages/airflow/operators/python.py", line 198, in execute_callable
    return self.python_callable(*self.op_args, **self.op_kwargs)
  File "/opt/airflow/dags/energy-prod-cons-dag/data_energy_dag.py", line 67, in _fetch_and_save
    df_conso_energy_region = df_conso_energy_region.drop([columns_to_drop_region], axis=1)
  File "/home/airflow/.local/lib/python3.7/site-packages/pandas/util/_decorators.py", line 311, in wrapper
    return func(*args, **kwargs)
  File "/home/airflow/.local/lib/python3.7/site-packages/pandas/core/frame.py", line 4913, in drop
    errors=errors,
  File "/home/airflow/.local/lib/python3.7/site-packages/pandas/core/generic.py", line 4150, in drop
    obj = obj._drop_axis(labels, axis, level=level, errors=errors)
  File "/home/airflow/.local/lib/python3.7/site-packages/pandas/core/generic.py", line 4185, in _drop_axis
    new_axis = axis.drop(labels, errors=errors)
  File "/home/airflow/.local/lib/python3.7/site-packages/pandas/core/indexes/base.py", line 6017, in drop
    raise KeyError(f"{labels[mask]} not found in axis")
KeyError: "[('libelle_grand_secteur', 'libelle_categorie_consommation', 'code_naf', 'nombre_mailles_secretisees')] not found in axis"
[2024-02-06T18:29:55.914+0000] {taskinstance.py:1350} INFO - Marking task as FAILED. dag_id=get_energy_data_send_psql, task_id=fetch_and_save, execution_date=20240206T182946, start_date=20240206T182950, end_date=20240206T182955
[2024-02-06T18:29:55.961+0000] {standard_task_runner.py:109} ERROR - Failed to execute job 112 for task fetch_and_save ("[('libelle_grand_secteur', 'libelle_categorie_consommation', 'code_naf', 'nombre_mailles_secretisees')] not found in axis"; 5210)
[2024-02-06T18:29:56.305+0000] {local_task_job_runner.py:225} INFO - Task exited with return code 1
[2024-02-06T18:29:56.583+0000] {taskinstance.py:2651} INFO - 0 downstream tasks scheduled from follow-on schedule check
