[2024-02-26T22:01:39.714+0000] {taskinstance.py:1103} INFO - Dependencies all met for dep_context=non-requeueable deps ti=<TaskInstance: EnergyWarehouse.load_conso_energy_region scheduled__2024-02-25T00:00:00+00:00 [queued]>
[2024-02-26T22:01:39.956+0000] {taskinstance.py:1103} INFO - Dependencies all met for dep_context=requeueable deps ti=<TaskInstance: EnergyWarehouse.load_conso_energy_region scheduled__2024-02-25T00:00:00+00:00 [queued]>
[2024-02-26T22:01:39.962+0000] {taskinstance.py:1308} INFO - Starting attempt 1 of 2
[2024-02-26T22:01:41.552+0000] {taskinstance.py:1327} INFO - Executing <Task(PythonOperator): load_conso_energy_region> on 2024-02-25 00:00:00+00:00
[2024-02-26T22:01:41.791+0000] {standard_task_runner.py:57} INFO - Started process 3858 to run task
[2024-02-26T22:01:42.110+0000] {standard_task_runner.py:84} INFO - Running: ['***', 'tasks', 'run', 'EnergyWarehouse', 'load_conso_energy_region', 'scheduled__2024-02-25T00:00:00+00:00', '--job-id', '408', '--raw', '--subdir', 'DAGS_FOLDER/***-to-bigquery-dag/***_to_bigquerry_dag.py', '--cfg-path', '/tmp/tmp8487k74f']
[2024-02-26T22:01:42.153+0000] {standard_task_runner.py:85} INFO - Job 408: Subtask load_conso_energy_region
[2024-02-26T22:01:42.963+0000] {task_command.py:410} INFO - Running <TaskInstance: EnergyWarehouse.load_conso_energy_region scheduled__2024-02-25T00:00:00+00:00 [running]> on host 952b3f8a1a94
[2024-02-26T22:01:49.219+0000] {taskinstance.py:1547} INFO - Exporting env vars: AIRFLOW_CTX_DAG_OWNER='Mbaye SENE' AIRFLOW_CTX_DAG_ID='EnergyWarehouse' AIRFLOW_CTX_TASK_ID='load_conso_energy_region' AIRFLOW_CTX_EXECUTION_DATE='2024-02-25T00:00:00+00:00' AIRFLOW_CTX_TRY_NUMBER='1' AIRFLOW_CTX_DAG_RUN_ID='scheduled__2024-02-25T00:00:00+00:00'
[2024-02-26T22:01:49.428+0000] {taskinstance.py:1824} ERROR - Task failed with exception
Traceback (most recent call last):
  File "/opt/airflow/dags/airflow-to-bigquery-dag/airflow_to_bigquerry_dag.py", line 46, in load_conso_energy_region
    df_conso_energy_region = pd.read_csv(source_conso_region, sep=';', error_bad_lines=False)
NameError: name 'pd' is not defined

During handling of the above exception, another exception occurred:

Traceback (most recent call last):
  File "/home/airflow/.local/lib/python3.7/site-packages/airflow/operators/python.py", line 181, in execute
    return_value = self.execute_callable()
  File "/home/airflow/.local/lib/python3.7/site-packages/airflow/operators/python.py", line 198, in execute_callable
    return self.python_callable(*self.op_args, **self.op_kwargs)
  File "/opt/airflow/dags/airflow-to-bigquery-dag/airflow_to_bigquerry_dag.py", line 58, in load_conso_energy_region
    except pd.errors.ParserError as e:
NameError: name 'pd' is not defined
[2024-02-26T22:01:50.168+0000] {taskinstance.py:1350} INFO - Marking task as UP_FOR_RETRY. dag_id=EnergyWarehouse, task_id=load_conso_energy_region, execution_date=20240225T000000, start_date=20240226T220139, end_date=20240226T220150
[2024-02-26T22:01:52.291+0000] {standard_task_runner.py:109} ERROR - Failed to execute job 408 for task load_conso_energy_region (name 'pd' is not defined; 3858)
[2024-02-26T22:01:52.847+0000] {local_task_job_runner.py:225} INFO - Task exited with return code 1
[2024-02-26T22:01:53.863+0000] {taskinstance.py:2651} INFO - 0 downstream tasks scheduled from follow-on schedule check
