[2024-03-13T13:20:10.230+0000] {taskinstance.py:1103} INFO - Dependencies all met for dep_context=non-requeueable deps ti=<TaskInstance: EnergyWarehouse.create_fact_table_conso_energy_region manual__2024-03-13T13:10:47.931563+00:00 [queued]>
[2024-03-13T13:20:10.272+0000] {taskinstance.py:1103} INFO - Dependencies all met for dep_context=requeueable deps ti=<TaskInstance: EnergyWarehouse.create_fact_table_conso_energy_region manual__2024-03-13T13:10:47.931563+00:00 [queued]>
[2024-03-13T13:20:10.288+0000] {taskinstance.py:1308} INFO - Starting attempt 1 of 2
[2024-03-13T13:20:10.368+0000] {taskinstance.py:1327} INFO - Executing <Task(PythonOperator): create_fact_table_conso_energy_region> on 2024-03-13 13:10:47.931563+00:00
[2024-03-13T13:20:10.398+0000] {standard_task_runner.py:57} INFO - Started process 559 to run task
[2024-03-13T13:20:10.539+0000] {standard_task_runner.py:84} INFO - Running: ['***', 'tasks', 'run', 'EnergyWarehouse', 'create_fact_table_conso_energy_region', 'manual__2024-03-13T13:10:47.931563+00:00', '--job-id', '1594', '--raw', '--subdir', 'DAGS_FOLDER/***-to-bigquery-dag/***_to_bigquerry_dag.py', '--cfg-path', '/tmp/tmpn92i_l7i']
[2024-03-13T13:20:10.576+0000] {standard_task_runner.py:85} INFO - Job 1594: Subtask create_fact_table_conso_energy_region
[2024-03-13T13:20:10.889+0000] {task_command.py:410} INFO - Running <TaskInstance: EnergyWarehouse.create_fact_table_conso_energy_region manual__2024-03-13T13:10:47.931563+00:00 [running]> on host 952b3f8a1a94
[2024-03-13T13:20:11.580+0000] {taskinstance.py:1547} INFO - Exporting env vars: AIRFLOW_CTX_DAG_OWNER='Mbaye SENE' AIRFLOW_CTX_DAG_ID='EnergyWarehouse' AIRFLOW_CTX_TASK_ID='create_fact_table_conso_energy_region' AIRFLOW_CTX_EXECUTION_DATE='2024-03-13T13:10:47.931563+00:00' AIRFLOW_CTX_TRY_NUMBER='1' AIRFLOW_CTX_DAG_RUN_ID='manual__2024-03-13T13:10:47.931563+00:00'
[2024-03-13T13:20:12.128+0000] {taskinstance.py:1824} ERROR - Task failed with exception
Traceback (most recent call last):
  File "/home/airflow/.local/lib/python3.7/site-packages/airflow/operators/python.py", line 181, in execute
    return_value = self.execute_callable()
  File "/home/airflow/.local/lib/python3.7/site-packages/airflow/operators/python.py", line 198, in execute_callable
    return self.python_callable(*self.op_args, **self.op_kwargs)
  File "/opt/airflow/dags/airflow-to-bigquery-dag/airflow_to_bigquerry_dag.py", line 431, in create_fact_table_conso_energy_region
    fact_table_conso_energy_region = df_conso_energy_region.merge(operateur_dim, on = 'operateur')\
NameError: name 'operateur_dim' is not defined
[2024-03-13T13:20:12.147+0000] {taskinstance.py:1350} INFO - Marking task as UP_FOR_RETRY. dag_id=EnergyWarehouse, task_id=create_fact_table_conso_energy_region, execution_date=20240313T131047, start_date=20240313T132010, end_date=20240313T132012
[2024-03-13T13:20:12.170+0000] {standard_task_runner.py:109} ERROR - Failed to execute job 1594 for task create_fact_table_conso_energy_region (name 'operateur_dim' is not defined; 559)
[2024-03-13T13:20:12.228+0000] {local_task_job_runner.py:225} INFO - Task exited with return code 1
[2024-03-13T13:20:12.285+0000] {taskinstance.py:2651} INFO - 0 downstream tasks scheduled from follow-on schedule check
