[2024-02-26T22:28:10.187+0000] {taskinstance.py:1103} INFO - Dependencies all met for dep_context=non-requeueable deps ti=<TaskInstance: EnergyWarehouse.load_prod_elect_dept manual__2024-02-26T22:27:55.775927+00:00 [queued]>
[2024-02-26T22:28:10.277+0000] {taskinstance.py:1103} INFO - Dependencies all met for dep_context=requeueable deps ti=<TaskInstance: EnergyWarehouse.load_prod_elect_dept manual__2024-02-26T22:27:55.775927+00:00 [queued]>
[2024-02-26T22:28:10.280+0000] {taskinstance.py:1308} INFO - Starting attempt 1 of 2
[2024-02-26T22:28:10.353+0000] {taskinstance.py:1327} INFO - Executing <Task(PythonOperator): load_prod_elect_dept> on 2024-02-26 22:27:55.775927+00:00
[2024-02-26T22:28:10.423+0000] {standard_task_runner.py:57} INFO - Started process 4583 to run task
[2024-02-26T22:28:10.504+0000] {standard_task_runner.py:84} INFO - Running: ['***', 'tasks', 'run', 'EnergyWarehouse', 'load_prod_elect_dept', 'manual__2024-02-26T22:27:55.775927+00:00', '--job-id', '509', '--raw', '--subdir', 'DAGS_FOLDER/***-to-bigquery-dag/***_to_bigquerry_dag.py', '--cfg-path', '/tmp/tmpawtsdrsy']
[2024-02-26T22:28:10.531+0000] {standard_task_runner.py:85} INFO - Job 509: Subtask load_prod_elect_dept
[2024-02-26T22:28:10.914+0000] {task_command.py:410} INFO - Running <TaskInstance: EnergyWarehouse.load_prod_elect_dept manual__2024-02-26T22:27:55.775927+00:00 [running]> on host 952b3f8a1a94
[2024-02-26T22:28:11.481+0000] {taskinstance.py:1547} INFO - Exporting env vars: AIRFLOW_CTX_DAG_OWNER='Mbaye SENE' AIRFLOW_CTX_DAG_ID='EnergyWarehouse' AIRFLOW_CTX_TASK_ID='load_prod_elect_dept' AIRFLOW_CTX_EXECUTION_DATE='2024-02-26T22:27:55.775927+00:00' AIRFLOW_CTX_TRY_NUMBER='1' AIRFLOW_CTX_DAG_RUN_ID='manual__2024-02-26T22:27:55.775927+00:00'
[2024-02-26T22:28:11.517+0000] {taskinstance.py:1824} ERROR - Task failed with exception
Traceback (most recent call last):
  File "/opt/airflow/dags/airflow-to-bigquery-dag/airflow_to_bigquerry_dag.py", line 95, in load_prod_elect_dept
    df_prod_elect_dept = pd.read_csv(prod_elect_mensuel_dept, sep=';', error_bad_lines=False)
NameError: name 'pd' is not defined

During handling of the above exception, another exception occurred:

Traceback (most recent call last):
  File "/home/airflow/.local/lib/python3.7/site-packages/airflow/operators/python.py", line 181, in execute
    return_value = self.execute_callable()
  File "/home/airflow/.local/lib/python3.7/site-packages/airflow/operators/python.py", line 198, in execute_callable
    return self.python_callable(*self.op_args, **self.op_kwargs)
  File "/opt/airflow/dags/airflow-to-bigquery-dag/airflow_to_bigquerry_dag.py", line 105, in load_prod_elect_dept
    except pd.errors.ParserError as e:
NameError: name 'pd' is not defined
[2024-02-26T22:28:11.601+0000] {taskinstance.py:1350} INFO - Marking task as UP_FOR_RETRY. dag_id=EnergyWarehouse, task_id=load_prod_elect_dept, execution_date=20240226T222755, start_date=20240226T222810, end_date=20240226T222811
[2024-02-26T22:28:11.663+0000] {standard_task_runner.py:109} ERROR - Failed to execute job 509 for task load_prod_elect_dept (name 'pd' is not defined; 4583)
[2024-02-26T22:28:11.757+0000] {local_task_job_runner.py:225} INFO - Task exited with return code 1
[2024-02-26T22:28:12.016+0000] {taskinstance.py:2651} INFO - 0 downstream tasks scheduled from follow-on schedule check
