[2024-02-27T10:52:32.438+0000] {taskinstance.py:1103} INFO - Dependencies all met for dep_context=non-requeueable deps ti=<TaskInstance: EnergyWarehouse.create_fact_table_prod_energy manual__2024-02-27T10:44:24.007709+00:00 [queued]>
[2024-02-27T10:52:32.504+0000] {taskinstance.py:1103} INFO - Dependencies all met for dep_context=requeueable deps ti=<TaskInstance: EnergyWarehouse.create_fact_table_prod_energy manual__2024-02-27T10:44:24.007709+00:00 [queued]>
[2024-02-27T10:52:32.512+0000] {taskinstance.py:1308} INFO - Starting attempt 2 of 2
[2024-02-27T10:52:32.663+0000] {taskinstance.py:1327} INFO - Executing <Task(PythonOperator): create_fact_table_prod_energy> on 2024-02-27 10:44:24.007709+00:00
[2024-02-27T10:52:32.690+0000] {standard_task_runner.py:57} INFO - Started process 16117 to run task
[2024-02-27T10:52:32.745+0000] {standard_task_runner.py:84} INFO - Running: ['***', 'tasks', 'run', 'EnergyWarehouse', 'create_fact_table_prod_energy', 'manual__2024-02-27T10:44:24.007709+00:00', '--job-id', '708', '--raw', '--subdir', 'DAGS_FOLDER/***-to-bigquery-dag/***_to_bigquerry_dag.py', '--cfg-path', '/tmp/tmp1u34op7y']
[2024-02-27T10:52:32.757+0000] {standard_task_runner.py:85} INFO - Job 708: Subtask create_fact_table_prod_energy
[2024-02-27T10:52:33.206+0000] {task_command.py:410} INFO - Running <TaskInstance: EnergyWarehouse.create_fact_table_prod_energy manual__2024-02-27T10:44:24.007709+00:00 [running]> on host 952b3f8a1a94
[2024-02-27T10:52:34.223+0000] {taskinstance.py:1547} INFO - Exporting env vars: AIRFLOW_CTX_DAG_OWNER='Mbaye SENE' AIRFLOW_CTX_DAG_ID='EnergyWarehouse' AIRFLOW_CTX_TASK_ID='create_fact_table_prod_energy' AIRFLOW_CTX_EXECUTION_DATE='2024-02-27T10:44:24.007709+00:00' AIRFLOW_CTX_TRY_NUMBER='2' AIRFLOW_CTX_DAG_RUN_ID='manual__2024-02-27T10:44:24.007709+00:00'
[2024-02-27T10:52:36.040+0000] {taskinstance.py:1824} ERROR - Task failed with exception
Traceback (most recent call last):
  File "/home/airflow/.local/lib/python3.7/site-packages/airflow/operators/python.py", line 181, in execute
    return_value = self.execute_callable()
  File "/home/airflow/.local/lib/python3.7/site-packages/airflow/operators/python.py", line 198, in execute_callable
    return self.python_callable(*self.op_args, **self.op_kwargs)
  File "/opt/airflow/dags/airflow-to-bigquery-dag/airflow_to_bigquerry_dag.py", line 330, in create_fact_table_prod_energy
    fact_table_prod_energy = df_prod_elect_dept.merge(annee_dim, on='annee')\
AttributeError: 'NoneType' object has no attribute 'merge'
[2024-02-27T10:52:36.120+0000] {taskinstance.py:1350} INFO - Marking task as FAILED. dag_id=EnergyWarehouse, task_id=create_fact_table_prod_energy, execution_date=20240227T104424, start_date=20240227T105232, end_date=20240227T105236
[2024-02-27T10:52:36.620+0000] {standard_task_runner.py:109} ERROR - Failed to execute job 708 for task create_fact_table_prod_energy ('NoneType' object has no attribute 'merge'; 16117)
[2024-02-27T10:52:36.968+0000] {local_task_job_runner.py:225} INFO - Task exited with return code 1
[2024-02-27T10:52:38.418+0000] {taskinstance.py:2651} INFO - 0 downstream tasks scheduled from follow-on schedule check
