[2024-02-19T22:11:14.518+0000] {taskinstance.py:1103} INFO - Dependencies all met for dep_context=non-requeueable deps ti=<TaskInstance: read_and_load_data_to_s3.reading_transform_csv manual__2024-02-19T22:11:12.852318+00:00 [queued]>
[2024-02-19T22:11:14.539+0000] {taskinstance.py:1103} INFO - Dependencies all met for dep_context=requeueable deps ti=<TaskInstance: read_and_load_data_to_s3.reading_transform_csv manual__2024-02-19T22:11:12.852318+00:00 [queued]>
[2024-02-19T22:11:14.542+0000] {taskinstance.py:1308} INFO - Starting attempt 1 of 1
[2024-02-19T22:11:14.572+0000] {taskinstance.py:1327} INFO - Executing <Task(PythonOperator): reading_transform_csv> on 2024-02-19 22:11:12.852318+00:00
[2024-02-19T22:11:14.586+0000] {standard_task_runner.py:57} INFO - Started process 2300 to run task
[2024-02-19T22:11:14.595+0000] {standard_task_runner.py:84} INFO - Running: ['***', 'tasks', 'run', 'read_and_load_data_to_s3', 'reading_transform_csv', 'manual__2024-02-19T22:11:12.852318+00:00', '--job-id', '285', '--raw', '--subdir', 'DAGS_FOLDER/energy-prod-cons-dag/data_energy_dag.py', '--cfg-path', '/tmp/tmpi1c9sb_0']
[2024-02-19T22:11:14.618+0000] {standard_task_runner.py:85} INFO - Job 285: Subtask reading_transform_csv
[2024-02-19T22:11:14.865+0000] {task_command.py:410} INFO - Running <TaskInstance: read_and_load_data_to_s3.reading_transform_csv manual__2024-02-19T22:11:12.852318+00:00 [running]> on host 952b3f8a1a94
[2024-02-19T22:11:15.020+0000] {taskinstance.py:1547} INFO - Exporting env vars: AIRFLOW_CTX_DAG_OWNER='***' AIRFLOW_CTX_DAG_ID='read_and_load_data_to_s3' AIRFLOW_CTX_TASK_ID='reading_transform_csv' AIRFLOW_CTX_EXECUTION_DATE='2024-02-19T22:11:12.852318+00:00' AIRFLOW_CTX_TRY_NUMBER='1' AIRFLOW_CTX_DAG_RUN_ID='manual__2024-02-19T22:11:12.852318+00:00'
[2024-02-19T22:11:15.024+0000] {warnings.py:110} WARNING - /home/***/.local/lib/python3.7/site-packages/***/operators/python.py:198: FutureWarning: The error_bad_lines argument has been deprecated and will be removed in a future version.


  return self.python_callable(*self.op_args, **self.op_kwargs)

[2024-02-19T22:11:15.046+0000] {taskinstance.py:1824} ERROR - Task failed with exception
Traceback (most recent call last):
  File "/home/airflow/.local/lib/python3.7/site-packages/airflow/operators/python.py", line 181, in execute
    return_value = self.execute_callable()
  File "/home/airflow/.local/lib/python3.7/site-packages/airflow/operators/python.py", line 198, in execute_callable
    return self.python_callable(*self.op_args, **self.op_kwargs)
  File "/opt/airflow/dags/energy-prod-cons-dag/data_energy_dag.py", line 443, in _reading_transform_csv
    print("***** display FACT TABLE CONSO ENERGY DEPT  :", fact_table_conso_energy_dept_.head(3))
AttributeError: 'str' object has no attribute 'head'
[2024-02-19T22:11:15.072+0000] {taskinstance.py:1350} INFO - Marking task as FAILED. dag_id=read_and_load_data_to_s3, task_id=reading_transform_csv, execution_date=20240219T221112, start_date=20240219T221114, end_date=20240219T221115
[2024-02-19T22:11:15.091+0000] {standard_task_runner.py:109} ERROR - Failed to execute job 285 for task reading_transform_csv ('str' object has no attribute 'head'; 2300)
[2024-02-19T22:11:15.144+0000] {local_task_job_runner.py:225} INFO - Task exited with return code 1
[2024-02-19T22:11:15.191+0000] {taskinstance.py:2651} INFO - 0 downstream tasks scheduled from follow-on schedule check
