[2023-06-14T13:08:21.365+0000] {taskinstance.py:1103} INFO - Dependencies all met for dep_context=non-requeueable deps ti=<TaskInstance: get_psql_send_s3.send_csv_s3 manual__2023-06-14T13:08:10.310666+00:00 [queued]>
[2023-06-14T13:08:21.395+0000] {taskinstance.py:1103} INFO - Dependencies all met for dep_context=requeueable deps ti=<TaskInstance: get_psql_send_s3.send_csv_s3 manual__2023-06-14T13:08:10.310666+00:00 [queued]>
[2023-06-14T13:08:21.398+0000] {taskinstance.py:1308} INFO - Starting attempt 1 of 1
[2023-06-14T13:08:21.439+0000] {taskinstance.py:1327} INFO - Executing <Task(PythonOperator): send_csv_s3> on 2023-06-14 13:08:10.310666+00:00
[2023-06-14T13:08:21.452+0000] {standard_task_runner.py:57} INFO - Started process 2440 to run task
[2023-06-14T13:08:21.466+0000] {standard_task_runner.py:84} INFO - Running: ['***', 'tasks', 'run', 'get_psql_send_s3', 'send_csv_s3', 'manual__2023-06-14T13:08:10.310666+00:00', '--job-id', '1504', '--raw', '--subdir', 'DAGS_FOLDER/end_to_end_pipeline_***.py', '--cfg-path', '/tmp/tmpd_7e82h8']
[2023-06-14T13:08:21.470+0000] {standard_task_runner.py:85} INFO - Job 1504: Subtask send_csv_s3
[2023-06-14T13:08:21.582+0000] {task_command.py:410} INFO - Running <TaskInstance: get_psql_send_s3.send_csv_s3 manual__2023-06-14T13:08:10.310666+00:00 [running]> on host cd01a659cc96
[2023-06-14T13:08:21.747+0000] {taskinstance.py:1547} INFO - Exporting env vars: AIRFLOW_CTX_DAG_OWNER='***' AIRFLOW_CTX_DAG_ID='get_psql_send_s3' AIRFLOW_CTX_TASK_ID='send_csv_s3' AIRFLOW_CTX_EXECUTION_DATE='2023-06-14T13:08:10.310666+00:00' AIRFLOW_CTX_TRY_NUMBER='1' AIRFLOW_CTX_DAG_RUN_ID='manual__2023-06-14T13:08:10.310666+00:00'
[2023-06-14T13:08:21.751+0000] {taskinstance.py:1824} ERROR - Task failed with exception
Traceback (most recent call last):
  File "/home/airflow/.local/lib/python3.7/site-packages/airflow/operators/python.py", line 181, in execute
    return_value = self.execute_callable()
  File "/home/airflow/.local/lib/python3.7/site-packages/airflow/operators/python.py", line 198, in execute_callable
    return self.python_callable(*self.op_args, **self.op_kwargs)
  File "/opt/airflow/dags/end_to_end_pipeline_airflow.py", line 90, in _send_csv_s3
    with open("/tmp/conf_file/configurations.json","r") as output:
FileNotFoundError: [Errno 2] No such file or directory: '/tmp/conf_file/configurations.json'
[2023-06-14T13:08:21.791+0000] {taskinstance.py:1350} INFO - Marking task as FAILED. dag_id=get_psql_send_s3, task_id=send_csv_s3, execution_date=20230614T130810, start_date=20230614T130821, end_date=20230614T130821
[2023-06-14T13:08:21.813+0000] {standard_task_runner.py:109} ERROR - Failed to execute job 1504 for task send_csv_s3 ([Errno 2] No such file or directory: '/tmp/conf_file/configurations.json'; 2440)
[2023-06-14T13:08:21.837+0000] {local_task_job_runner.py:225} INFO - Task exited with return code 1
[2023-06-14T13:08:21.862+0000] {taskinstance.py:2651} INFO - 0 downstream tasks scheduled from follow-on schedule check
