[2024-02-19T22:27:39.604+0000] {taskinstance.py:1103} INFO - Dependencies all met for dep_context=non-requeueable deps ti=<TaskInstance: read_and_load_data_to_s3.send_csv_s3 manual__2024-02-19T22:27:36.089563+00:00 [queued]>
[2024-02-19T22:27:39.623+0000] {taskinstance.py:1103} INFO - Dependencies all met for dep_context=requeueable deps ti=<TaskInstance: read_and_load_data_to_s3.send_csv_s3 manual__2024-02-19T22:27:36.089563+00:00 [queued]>
[2024-02-19T22:27:39.626+0000] {taskinstance.py:1308} INFO - Starting attempt 1 of 1
[2024-02-19T22:27:39.680+0000] {taskinstance.py:1327} INFO - Executing <Task(PythonOperator): send_csv_s3> on 2024-02-19 22:27:36.089563+00:00
[2024-02-19T22:27:39.695+0000] {standard_task_runner.py:57} INFO - Started process 2621 to run task
[2024-02-19T22:27:39.702+0000] {standard_task_runner.py:84} INFO - Running: ['***', 'tasks', 'run', 'read_and_load_data_to_s3', 'send_csv_s3', 'manual__2024-02-19T22:27:36.089563+00:00', '--job-id', '300', '--raw', '--subdir', 'DAGS_FOLDER/energy-prod-cons-dag/data_energy_dag.py', '--cfg-path', '/tmp/tmpdy75j3xd']
[2024-02-19T22:27:39.726+0000] {standard_task_runner.py:85} INFO - Job 300: Subtask send_csv_s3
[2024-02-19T22:27:39.897+0000] {task_command.py:410} INFO - Running <TaskInstance: read_and_load_data_to_s3.send_csv_s3 manual__2024-02-19T22:27:36.089563+00:00 [running]> on host 952b3f8a1a94
[2024-02-19T22:27:40.096+0000] {taskinstance.py:1547} INFO - Exporting env vars: AIRFLOW_CTX_DAG_OWNER='***' AIRFLOW_CTX_DAG_ID='read_and_load_data_to_s3' AIRFLOW_CTX_TASK_ID='send_csv_s3' AIRFLOW_CTX_EXECUTION_DATE='2024-02-19T22:27:36.089563+00:00' AIRFLOW_CTX_TRY_NUMBER='1' AIRFLOW_CTX_DAG_RUN_ID='manual__2024-02-19T22:27:36.089563+00:00'
[2024-02-19T22:27:40.688+0000] {taskinstance.py:1824} ERROR - Task failed with exception
Traceback (most recent call last):
  File "/home/airflow/.local/lib/python3.7/site-packages/airflow/operators/python.py", line 181, in execute
    return_value = self.execute_callable()
  File "/home/airflow/.local/lib/python3.7/site-packages/airflow/operators/python.py", line 198, in execute_callable
    return self.python_callable(*self.op_args, **self.op_kwargs)
  File "/opt/airflow/dags/energy-prod-cons-dag/data_energy_dag.py", line 485, in _send_csv_s3
    for file_path in file_paths:
NameError: name 'file_paths' is not defined
[2024-02-19T22:27:40.719+0000] {taskinstance.py:1350} INFO - Marking task as FAILED. dag_id=read_and_load_data_to_s3, task_id=send_csv_s3, execution_date=20240219T222736, start_date=20240219T222739, end_date=20240219T222740
[2024-02-19T22:27:40.770+0000] {standard_task_runner.py:109} ERROR - Failed to execute job 300 for task send_csv_s3 (name 'file_paths' is not defined; 2621)
[2024-02-19T22:27:40.837+0000] {local_task_job_runner.py:225} INFO - Task exited with return code 1
[2024-02-19T22:27:40.884+0000] {taskinstance.py:2651} INFO - 0 downstream tasks scheduled from follow-on schedule check
