[2024-02-24T15:48:55.785+0000] {taskinstance.py:1103} INFO - Dependencies all met for dep_context=non-requeueable deps ti=<TaskInstance: extract_energy_data_and_transform.send_csv_s3 manual__2024-02-24T15:47:16.158100+00:00 [queued]>
[2024-02-24T15:48:55.840+0000] {taskinstance.py:1103} INFO - Dependencies all met for dep_context=requeueable deps ti=<TaskInstance: extract_energy_data_and_transform.send_csv_s3 manual__2024-02-24T15:47:16.158100+00:00 [queued]>
[2024-02-24T15:48:55.847+0000] {taskinstance.py:1308} INFO - Starting attempt 1 of 1
[2024-02-24T15:48:55.985+0000] {taskinstance.py:1327} INFO - Executing <Task(PythonOperator): send_csv_s3> on 2024-02-24 15:47:16.158100+00:00
[2024-02-24T15:48:56.021+0000] {standard_task_runner.py:57} INFO - Started process 4438 to run task
[2024-02-24T15:48:56.071+0000] {standard_task_runner.py:84} INFO - Running: ['***', 'tasks', 'run', 'extract_energy_data_and_transform', 'send_csv_s3', 'manual__2024-02-24T15:47:16.158100+00:00', '--job-id', '385', '--raw', '--subdir', 'DAGS_FOLDER/energy-prod-cons-dag/data_energy_dag.py', '--cfg-path', '/tmp/tmpj2qm2afr']
[2024-02-24T15:48:56.103+0000] {standard_task_runner.py:85} INFO - Job 385: Subtask send_csv_s3
[2024-02-24T15:48:56.740+0000] {task_command.py:410} INFO - Running <TaskInstance: extract_energy_data_and_transform.send_csv_s3 manual__2024-02-24T15:47:16.158100+00:00 [running]> on host 952b3f8a1a94
[2024-02-24T15:48:57.771+0000] {taskinstance.py:1547} INFO - Exporting env vars: AIRFLOW_CTX_DAG_OWNER='***' AIRFLOW_CTX_DAG_ID='extract_energy_data_and_transform' AIRFLOW_CTX_TASK_ID='send_csv_s3' AIRFLOW_CTX_EXECUTION_DATE='2024-02-24T15:47:16.158100+00:00' AIRFLOW_CTX_TRY_NUMBER='1' AIRFLOW_CTX_DAG_RUN_ID='manual__2024-02-24T15:47:16.158100+00:00'
[2024-02-24T15:49:07.232+0000] {taskinstance.py:1824} ERROR - Task failed with exception
Traceback (most recent call last):
  File "/home/airflow/.local/lib/python3.7/site-packages/airflow/operators/python.py", line 181, in execute
    return_value = self.execute_callable()
  File "/home/airflow/.local/lib/python3.7/site-packages/airflow/operators/python.py", line 198, in execute_callable
    return self.python_callable(*self.op_args, **self.op_kwargs)
  File "/opt/airflow/dags/energy-prod-cons-dag/data_energy_dag.py", line 299, in _send_csv_s3
    directory_path + file_name)
  File "/home/airflow/.local/lib/python3.7/site-packages/boto3/s3/inject.py", line 148, in upload_file
    callback=Callback,
  File "/home/airflow/.local/lib/python3.7/site-packages/boto3/s3/transfer.py", line 292, in upload_file
    future.result()
  File "/home/airflow/.local/lib/python3.7/site-packages/s3transfer/futures.py", line 103, in result
    return self._coordinator.result()
  File "/home/airflow/.local/lib/python3.7/site-packages/s3transfer/futures.py", line 266, in result
    raise self._exception
  File "/home/airflow/.local/lib/python3.7/site-packages/s3transfer/tasks.py", line 269, in _main
    self._submit(transfer_future=transfer_future, **kwargs)
  File "/home/airflow/.local/lib/python3.7/site-packages/s3transfer/upload.py", line 585, in _submit
    upload_input_manager.provide_transfer_size(transfer_future)
  File "/home/airflow/.local/lib/python3.7/site-packages/s3transfer/upload.py", line 244, in provide_transfer_size
    self._osutil.get_file_size(transfer_future.meta.call_args.fileobj)
  File "/home/airflow/.local/lib/python3.7/site-packages/s3transfer/utils.py", line 247, in get_file_size
    return os.path.getsize(filename)
  File "/usr/local/lib/python3.7/genericpath.py", line 50, in getsize
    return os.stat(filename).st_size
NotADirectoryError: [Errno 20] Not a directory: '/tmp/csv_file/dim_secteur_naf.csv/tmp/csv_file/dim_annee.csv'
[2024-02-24T15:49:07.415+0000] {taskinstance.py:1350} INFO - Marking task as FAILED. dag_id=extract_energy_data_and_transform, task_id=send_csv_s3, execution_date=20240224T154716, start_date=20240224T154855, end_date=20240224T154907
[2024-02-24T15:49:07.549+0000] {standard_task_runner.py:109} ERROR - Failed to execute job 385 for task send_csv_s3 ([Errno 20] Not a directory: '/tmp/csv_file/dim_secteur_naf.csv/tmp/csv_file/dim_annee.csv'; 4438)
[2024-02-24T15:49:07.651+0000] {local_task_job_runner.py:225} INFO - Task exited with return code 1
[2024-02-24T15:49:07.783+0000] {taskinstance.py:2651} INFO - 0 downstream tasks scheduled from follow-on schedule check
